Workbook

Sheet kamus
A1: No | B1: desa | C1: kecamatan | D1: puskesmas | E1: penduduk 2020 | F1: penduduk 2021 | G1: penduduk 2022 | H1: penduduk 2023 | I1: penduduk 2024 | J1: st_wolbachia (=1)
A2: 1 | B2: Kalitirto | C2: BERBAH | D2: Berbah | E2: 14565 | F2: 14673 | G2: 14825 | H2: 14973 | I2: 14469 | J2: 1
A3: 2 | B3: Sendangtirto | C3: BERBAH | D3: Berbah | E3: 18704 | F3: 18842 | G3: 19037 | H3: 19227 | I3: 18580 | J3: 1
A4: 3 | B4: Tegaltirto | C4: BERBAH | D4: Berbah | E4: 13363 | F4: 13463 | G4: 13601 | H4: 13737 | I4: 13275 | J4: 1
A5: 4 | B5: Jogotirto | C5: BERBAH | D5: Berbah | E5: 11448 | F5: 11533 | G5: 11652 | H5: 11768 | I5: 11372 | J5: 0
A6: 5 | B6: Glagaharjo | C6: CANGKRINGAN | D6: cangkringan | E6: 4133 | F6: 4164 | G6: 4207 | H6: 4249 | I6: 4106 | J6: 0
A7: 6 | B7: Wukirsari | C7: CANGKRINGAN | D7: cangkringan | E7: 11339 | F7: 11423 | G7: 11541 | H7: 11656 | I7: 11264 | J7: 0
A8: 7 | B8: Kepuharjo | C8: CANGKRINGAN | D8: cangkringan | E8: 3586 | F8: 3612 | G8: 3650 | H8: 3686 | I8: 3562 | J8: 0
A9: 8 | B9: Umbulharjo | C9: CANGKRINGAN | D9: cangkringan | E9: 5550 | F9: 5591 | G9: 5649 | H9: 5705 | I9: 5513 | J9: 0
A10: 9 | B10: Argomulyo | C10: CANGKRINGAN | D10: cangkringan | E10: 8063 | F10: 8123 | G10: 8207 | H10: 8289 | I10: 8010 | J10: 0
A11: 10 | B11: Maguwoharjo | C11: DEPOK | D11: Depok 1 | E11: 37946 | F11: 38228 | G11: 38622 | H11: 39007 | I11: 37695 | J11: 1
A12: 11 | B12: Condongcatur | C12: DEPOK | D12: Depok 2 | E12: 44433 | F12: 44763 | G12: 45224 | H12: 45676 | I12: 44139 | J12: 1
A13: 12 | B13: Caturtunggal | C13: DEPOK | D13: Depok 3 | E13: 44837 | F13: 45169 | G13: 45635 | H13: 46091 | I13: 44540 | J13: 1
... A87: 86 | B87: Donokerto | C87: TURI | D87: turi | E87: 9559 | F87: 9630 | G87: 9730 | H87: 9827 | I87: 9496 | J87: 0

Sheet spatial
A1: No | B1: kecamatan | C1: puskesmas | D1: desa | E1: st_wolbachia (=1) | F1: luas wilayah m2 | G1: % pemukiman | H1: luas wilayah (km2) | I1: kepadatan penduduk | J1: penduduk 2020 | K1: penduduk 2021 | L1: penduduk 2022 | M1: penduduk 2023 | N1: penduduk 2024 | O1: kasus 2020 | P1: kasus 2021 | Q1: kasus 2022 | R1: kasus 2023 | S1: kasus 2024 | T1: kasus 2025 | U1: IR 2020 | V1: IR 2021 | W1: IR 2022 | X1: IR 2023 | Y1: IR 2024 | Z1: IR 2025 | AA1: rerata IR | AB1: Median IR | AC1: IR_median(%) | AD1: endemisitas | AE1: immunity | AF1: morbiditas | AG1: DSI | AH1: ABJ | AI1: HI | AJ1: rumah diperiksa (%) | AK1: ketinggian_mean | AL1: ketinggian_median | AM1: ketinggian_SD | AN1: ketinggian_min | AO1: ketinggian_max
A2: 1 | B2: BERBAH | C2: Berbah | D2: Kalitirto | E2: 1 | F2: 6279011.6 | G2: 13.77 | H2: 6.28 | I2: 2304 | J2: 14565 | K2: 14673 | L2: 14825 | M2: 14973 | N2: 14469 | O2: 37 | P2: 17 | Q2: 11 | R2: 9 | S2: 30 | T2: 20 | U2: =O2/J2*100000 -> 254.03364 | V2: =P2/K2*100000 -> 115.85906 | W2: =Q2/L2*100000 -> 74.198988 | X2: =R2/M2*100000 -> 60.108195 | Y2: =S2/N2*100000 -> 207.33983 | Z2: =T2/N2*100000 -> 138.22655 | AA2: =AVERAGE(U2:Y2) -> 142.30794 | AB2: =MEDIAN(U2:Y2) -> 115.85906 | AC2: =IF(AB2=0,(Z2-0.01)/0.01,(Z2-AB2)/AB2) -> 0.19305777 | AD2: =COUNTIF(O2:S2,">0") -> 5 | AE2: =IF(AA2<50,1,IF(AA2<101,2,IF(AA2<151,3,IF(AA2<201,4,5)))) -> 3 | AF2: =IF(AC2<-50%,1,IF(AC2<-10%,2,IF(AC2<10%,3,IF(AC2<51%,4,5)))) -> 4 | AG2: =AD2+AE2+AF2 -> 12 | AH2: 98.226601 | AI2: 1.773399 | AJ2: 26.473657 | AK2: 106.62523 | AL2: 106.98101 | AM2: 9.0298578 | AN2: 74.44146 | AO2: 128.71031
A3: 2 | B3: BERBAH | C3: Berbah | D3: Sendangtirto | E3: 1 | F3: 5453465.2 | G3: 16.86 | H3: 5.45 | I3: 3407 | J3: 18704 | K3: 18842 | L3: 19037 | M3: 19227 | N3: 18580 | O3: 26 | P3: 5 | Q3: 26 | R3: 11 | S3: 17 | T3: 24 | U3: =O3/J3*100000 -> 139.0077 | V3: =P3/K3*100000 -> 26.536461 | W3: =Q3/L3*100000 -> 136.57614 | X3: =R3/M3*100000 -> 57.211213 | Y3: =S3/N3*100000 -> 91.496233 | Z3: =T3/N3*100000 -> 129.17115 | AA3: =AVERAGE(U3:Y3) -> 90.165549 | AB3: =MEDIAN(U3:Y3) -> 91.496233 | AC3: =IF(AB3=0,(Z3-0.01)/0.01,(Z3-AB3)/AB3) -> 0.41176471 | AD3: =COUNTIF(O3:S3,">0") -> 5 | AE3: =IF(AA3<50,1,IF(AA3<101,2,IF(AA3<151,3,IF(AA3<201,4,5)))) -> 2 | AF3: =IF(AC3<-50%,1,IF(AC3<-10%,2,IF(AC3<10%,3,IF(AC3<51%,4,5)))) -> 4 | AG3: =AD3+AE3+AF3 -> 11 | AH3: 95.853899 | AI3: 4.1461007 | AJ3: 20.576884 | AK3: 88.824592 | AL3: 89.240211 | AM3: 7.3364995 | AN3: 67.643204 | AO3: 110.91736
A4: 3 | B4: BERBAH | C4: Berbah | D4: Tegaltirto | E4: 1 | F4: 5557512.7 | G4: 9.55 | H4: 5.56 | I4: 2389 | J4: 13363 | K4: 13463 | L4: 13601 | M4: 13737 | N4: 13275 | O4: 12 | P4: 5 | Q4: 3 | R4: 10 | S4: 17 | T4: 22 | U4: =O4/J4*100000 -> 89.800195 | V4: =P4/K4*100000 -> 37.138825 | W4: =Q4/L4*100000 -> 22.057202 | X4: =R4/M4*100000 -> 72.796098 | Y4: =S4/N4*100000 -> 128.06026 | Z4: =T4/N4*100000 -> 165.72505 | AA4: =AVERAGE(U4:Y4) -> 69.970517 | AB4: =MEDIAN(U4:Y4) -> 72.796098 | AC4: =IF(AB4=0,(Z4-0.01)/0.01,(Z4-AB4)/AB4) -> 1.276565 | AD4: =COUNTIF(O4:S4,">0") -> 5 | AE4: =IF(AA4<50,1,IF(AA4<101,2,IF(AA4<151,3,IF(AA4<201,4,5)))) -> 2 | AF4: =IF(AC4<-50%,1,IF(AC4<-10%,2,IF(AC4<10%,3,IF(AC4<51%,4,5)))) -> 5 | AG4: =AD4+AE4+AF4 -> 12 | AH4: 97.510373 | AI4: 2.4896266 | AJ4: 47.967017 | AK4: 94.678601 | AL4: 91.71563 | AM4: 11.035832 | AN4: 69.403664 | AO4: 123.96963
A5: 4 | B5: BERBAH | C5: Berbah | D5: Jogotirto | E5: 0 | F5: 5839758.4 | G5: 10.47 | H5: 5.84 | I5: 1947 | J5: 11448 | K5: 11533 | L5: 11652 | M5: 11768 | N5: 11372 | O5: 24 | P5: 6 | Q5: 23 | R5: 6 | S5: 35 | T5: 51 | U5: =O5/J5*100000 -> 209.64361 | V5: =P5/K5*100000 -> 52.024625 | W5: =Q5/L5*100000 -> 197.39101 | X5: =R5/M5*100000 -> 50.985724 | Y5: =S5/N5*100000 -> 307.77348 | Z5: =T5/N5*100000 -> 448.46993 | AA5: =AVERAGE(U5:Y5) -> 163.56369 | AB5: =MEDIAN(U5:Y5) -> 197.39101 | AC5: =IF(AB5=0,(Z5-0.01)/0.01,(Z5-AB5)/AB5) -> 1.2719876 | AD5: =COUNTIF(O5:S5,">0") -> 5 | AE5: =IF(AA5<50,1,IF(AA5<101,2,IF(AA5<151,3,IF(AA5<201,4,5)))) -> 4 | AF5: =IF(AC5<-50%,1,IF(AC5<-10%,2,IF(AC5<10%,3,IF(AC5<51%,4,5)))) -> 5 | AG5: =AD5+AE5+AF5 -> 14 | AH5: 88.26087 | AI5: 11.73913 | AJ5: 22.900763 | AK5: 95.544823 | AL5: 94.460609 | AM5: 8.5351184 | AN5: 73.477081 | AO5: 140.70663
A6: 5 | B6: CANGKRINGAN | C6: cangkringan | D6: Glagaharjo | E6: 0 | F6: 7993731.6 | G6: 11.91 | H6: 7.99 | I6: 514 | J6: 4133 | K6: 4164 | L6: 4207 | M6: 4249 | N6: 4106 | O6: 2 | P6: 0 | Q6: 4 | R6: 0 | S6: 6 | T6: 4 | U6: =O6/J6*100000 -> 48.390999 | V6: =P6/K6*100000 -> 0 | W6: =Q6/L6*100000 -> 95.079629 | X6: =R6/M6*100000 -> 0 | Y6: =S6/N6*100000 -> 146.12762 | Z6: =T6/N6*100000 -> 97.418412 | AA6: =AVERAGE(U6:Y6) -> 57.919649 | AB6: =MEDIAN(U6:Y6) -> 48.390999 | AC6: =IF(AB6=0,(Z6-0.01)/0.01,(Z6-AB6)/AB6) -> 1.0131515 | AD6: =COUNTIF(O6:S6,">0") -> 3 | AE6: =IF(AA6<50,1,IF(AA6<101,2,IF(AA6<151,3,IF(AA6<201,4,5)))) -> 2 | AF6: =IF(AC6<-50%,1,IF(AC6<-10%,2,IF(AC6<10%,3,IF(AC6<51%,4,5)))) -> 5 | AG6: =AD6+AE6+AF6 -> 10 | AH6: 85.014409 | AI6: 14.985591 | AJ6: 29.991357 | AK6: 825.8767 | AL6: 778.81592 | AM6: 245.51977 | AN6: 462.74673 | AO6: 1398.238
A7: 6 | B7: CANGKRINGAN | C7: cangkringan | D7: Wukirsari | E7: 0 | F7: 12451182 | G7: 18.25 | H7: 12.45 | I7: 905 | J7: 11339 | K7: 11423 | L7: 11541 | M7: 11656 | N7: 11264 | O7: 4 | P7: 0 | Q7: 4 | R7: 6 | S7: 7 | T7: 18 | U7: =O7/J7*100000 -> 35.276479 | V7: =P7/K7*100000 -> 0 | W7: =Q7/L7*100000 -> 34.659042 | X7: =R7/M7*100000 -> 51.475635 | Y7: =S7/N7*100000 -> 62.144886 | Z7: =T7/N7*100000 -> 159.80114 | AA7: =AVERAGE(U7:Y7) -> 36.711208 | AB7: =MEDIAN(U7:Y7) -> 35.276479 | AC7: =IF(AB7=0,(Z7-0.01)/0.01,(Z7-AB7)/AB7) -> 3.5299627 | AD7: =COUNTIF(O7:S7,">0") -> 4 | AE7: =IF(AA7<50,1,IF(AA7<101,2,IF(AA7<151,3,IF(AA7<201,4,5)))) -> 1 | AF7: =IF(AC7<-50%,1,IF(AC7<-10%,2,IF(AC7<10%,3,IF(AC7<51%,4,5)))) -> 5 | AG7: =AD7+AE7+AF7 -> 10 | AH7: 96.153846 | AI7: 3.8461538 | AJ7: 36.031496 | AK7: 489.73962 | AL7: 489.18585 | AM7: 60.826609 | AN7: 374.19681 | AO7: 641.31598
A8: 7 | B8: CANGKRINGAN | C8: cangkringan | D8: Kepuharjo | E8: 0 | F8: 7672688.6 | G8: 6.89 | H8: 7.67 | I8: 464 | J8: 3586 | K8: 3612 | L8: 3650 | M8: 3686 | N8: 3562 | O8: 1 | P8: 1 | Q8: 1 | R8: 0 | S8: 9 | T8: 6 | U8: =O8/J8*100000 -> 27.886224 | V8: =P8/K8*100000 -> 27.685493 | W8: =Q8/L8*100000 -> 27.39726 | X8: =R8/M8*100000 -> 0 | Y8: =S8/N8*100000 -> 252.66704 | Z8: =T8/N8*100000 -> 168.44469 | AA8: =AVERAGE(U8:Y8) -> 67.127204 | AB8: =MEDIAN(U8:Y8) -> 27.685493 | AC8: =IF(AB8=0,(Z8-0.01)/0.01,(Z8-AB8)/AB8) -> 5.0842223 | AD8: =COUNTIF(O8:S8,">0") -> 4 | AE8: =IF(AA8<50,1,IF(AA8<101,2,IF(AA8<151,3,IF(AA8<201,4,5)))) -> 2 | AF8: =IF(AC8<-50%,1,IF(AC8<-10%,2,IF(AC8<10%,3,IF(AC8<51%,4,5)))) -> 5 | AG8: =AD8+AE8+AF8 -> 11 | AH8: 88.198758 | AI8: 11.801242 | AJ8: 32.071713 | AK8: 808.09605 | AL8: 757.82526 | AM8: 168.00882 | AN8: 590.66223 | AO8: 1332.4939
A9: 8 | B9: CANGKRINGAN | C9: cangkringan | D9: Umbulharjo | E9: 0 | F9: 9473638.4 | G9: 10.37 | H9: 9.47 | I9: 582 | J9: 5550 | K9: 5591 | L9: 5649 | M9: 5705 | N9: 5513 | O9: 1 | P9: 1 | Q9: 1 | R9: 2 | S9: 1 | T9: 8 | U9: =O9/J9*100000 -> 18.018018 | V9: =P9/K9*100000 -> 17.885888 | W9: =Q9/L9*100000 -> 17.702248 | X9: =R9/M9*100000 -> 35.056968 | Y9: =S9/N9*100000 -> 18.138944 | Z9: =T9/N9*100000 -> 145.11155 | AA9: =AVERAGE(U9:Y9) -> 21.360413 | AB9: =MEDIAN(U9:Y9) -> 18.018018 | AC9: =IF(AB9=0,(Z9-0.01)/0.01,(Z9-AB9)/AB9) -> 7.0536913 | AD9: =COUNTIF(O9:S9,">0") -> 5 | AE9: =IF(AA9<50,1,IF(AA9<101,2,IF(AA9<151,3,IF(AA9<201,4,5)))) -> 1 | AF9: =IF(AC9<-50%,1,IF(AC9<-10%,2,IF(AC9<10%,3,IF(AC9<51%,4,5)))) -> 5 | AG9: =AD9+AE9+AF9 -> 11 | AH9: 100 | AI9: 0 | AJ9: 21.814672 | AK9: 766.97109 | AL9: 728.30261 | AM9: 172.05657 | AN9: 473.8732 | AO9: 1352.0422
A10: 9 | B10: CANGKRINGAN | C10: cangkringan | D10: Argomulyo | E10: 0 | F10: 7718805 | G10: 22.9 | H10: 7.72 | I10: 1038 | J10: 8063 | K10: 8123 | L10: 8207 | M10: 8289 | N10: 8010 | O10: 1 | P10: 2 | Q10: 6 | R10: 1 | S10: 14 | T10: 12 | U10: =O10/J10*100000 -> 12.402332 | V10: =P10/K10*100000 -> 24.621445 | W10: =Q10/L10*100000 -> 73.108322 | X10: =R10/M10*100000 -> 12.064181 | Y10: =S10/N10*100000 -> 174.78152 | Z10: =T10/N10*100000 -> 149.81273 | AA10: =AVERAGE(U10:Y10) -> 59.395561 | AB10: =MEDIAN(U10:Y10) -> 24.621445 | AC10: =IF(AB10=0,(Z10-0.01)/0.01,(Z10-AB10)/AB10) -> 5.0846442 | AD10: =COUNTIF(O10:S10,">0") -> 5 | AE10: =IF(AA10<50,1,IF(AA10<101,2,IF(AA10<151,3,IF(AA10<201,4,5)))) -> 2 | AF10: =IF(AC10<-50%,1,IF(AC10<-10%,2,IF(AC10<10%,3,IF(AC10<51%,4,5)))) -> 5 | AG10: =AD10+AE10+AF10 -> 12 | AH10: 100 | AI10: 0 | AJ10: 36.093888 | AK10: 394.07111 | AL10: 393.32678 | AM10: 38.771007 | AN10: 80.154503 | AO10: 489.98975
A11: 10 | B11: DEPOK | C11: Depok 1 | D11: Maguwoharjo | E11: 1 | F11: 15350113 | G11: 11.77 | H11: 15.35 | I11: 2456 | J11: 37946 | K11: 38228 | L11: 38622 | M11: 39007 | N11: 37695 | O11: 36 | P11: 16 | Q11: 14 | R11: 6 | S11: 32 | T11: 27 | U11: =O11/J11*100000 -> 94.87166 | V11: =P11/K11*100000 -> 41.854138 | W11: =Q11/L11*100000 -> 36.24877 | X11: =R11/M11*100000 -> 15.381855 | Y11: =S11/N11*100000 -> 84.891895 | Z11: =T11/N11*100000 -> 71.627537 | AA11: =AVERAGE(U11:Y11) -> 54.649664 | AB11: =MEDIAN(U11:Y11) -> 41.854138 | AC11: =IF(AB11=0,(Z11-0.01)/0.01,(Z11-AB11)/AB11) -> 0.71136092 | AD11: =COUNTIF(O11:S11,">0") -> 5 | AE11: =IF(AA11<50,1,IF(AA11<101,2,IF(AA11<151,3,IF(AA11<201,4,5)))) -> 2 | AF11: =IF(AC11<-50%,1,IF(AC11<-10%,2,IF(AC11<10%,3,IF(AC11<51%,4,5)))) -> 5 | AG11: =AD11+AE11+AF11 -> 12 | AH11: 90.411138 | AI11: 9.588862 | AJ11: 158.06385 | AK11: 136.44325 | AL11: 136.36624 | AM11: 20.636666 | AN11: 96.269791 | AO11: 182.85393
A12: 11 | B12: DEPOK | C12: Depok 2 | D12: Condongcatur | E12: 1 | F12: 8806615.7 | G12: 28.26 | H12: 8.81 | I12: 5012 | J12: 44433 | K12: 44763 | L12: 45224 | M12: 45676 | N12: 44139 | O12: 61 | P12: 30 | Q12: 29 | R12: 15 | S12: 80 | T12: 48 | U12: =O12/J12*100000 -> 137.28535 | V12: =P12/K12*100000 -> 67.019637 | W12: =Q12/L12*100000 -> 64.125243 | X12: =R12/M12*100000 -> 32.840004 | Y12: =S12/N12*100000 -> 181.24561 | Z12: =T12/N12*100000 -> 108.74737 | AA12: =AVERAGE(U12:Y12) -> 96.503169 | AB12: =MEDIAN(U12:Y12) -> 67.019637 | AC12: =IF(AB12=0,(Z12-0.01)/0.01,(Z12-AB12)/AB12) -> 0.62261945 | AD12: =COUNTIF(O12:S12,">0") -> 5 | AE12: =IF(AA12<50,1,IF(AA12<101,2,IF(AA12<151,3,IF(AA12<201,4,5)))) -> 2 | AF12: =IF(AC12<-50%,1,IF(AC12<-10%,2,IF(AC12<10%,3,IF(AC12<51%,4,5)))) -> 5 | AG12: =AD12+AE12+AF12 -> 12 | AH12: 92.192817 | AI12: 7.8071834 | AJ12: 223.52742 | AK12: 161.40281 | AL12: 160.34607 | AM12: 15.498034 | AN12: 121.12942 | AO12: 207.93137
A13: 12 | B13: DEPOK | C13: Depok 3 | D13: Caturtunggal | E13: 1 | F13: 10668406 | G13: 18.6 | H13: 10.67 | I13: 4175 | J13: 44837 | K13: 45169 | L13: 45635 | M13: 46091 | N13: 44540 | O13: 24 | P13: 11 | Q13: 9 | R13: 11 | S13: 36 | T13: 30 | U13: =O13/J13*100000 -> 53.527221 | V13: =P13/K13*100000 -> 24.352985 | W13: =Q13/L13*100000 -> 19.721705 | X13: =R13/M13*100000 -> 23.865831 | Y13: =S13/N13*100000 -> 80.826224 | Z13: =T13/N13*100000 -> 67.355186 | AA13: =AVERAGE(U13:Y13) -> 40.458793 | AB13: =MEDIAN(U13:Y13) -> 24.352985 | AC13: =IF(AB13=0,(Z13-0.01)/0.01,(Z13-AB13)/AB13) -> 1.7657876 | AD13: =COUNTIF(O13:S13,">0") -> 5 | AE13: =IF(AA13<50,1,IF(AA13<101,2,IF(AA13<151,3,IF(AA13<201,4,5)))) -> 1 | AF13: =IF(AC13<-50%,1,IF(AC13<-10%,2,IF(AC13<10%,3,IF(AC13<51%,4,5)))) -> 5 | AG13: =AD13+AE13+AF13 -> 11 | AH13: 92.399248 | AI13: 7.6007524 | AJ13: 384.3688 | AK13: 135.33847 | AL13: 134.08095 | AM13: 11.119062 | AN13: 106.4479 | AO13: 168.57657
... A87: 86 | B87: TURI | C87: turi | D87: Donokerto | E87: 0 | F87: 7214248.7 | G87: 21.07 | H87: 7.21 | I87: 1316 | J87: 9559 | K87: 9630 | L87: 9730 | M87: 9827 | N87: 9496 | O87: 0 | P87: 19 | Q87: 2 | R87: 3 | S87: 20 | T87: 9 | U87: =O87/J87*100000 -> 0 | V87: =P87/K87*100000 -> 197.3001 | W87: =Q87/L87*100000 -> 20.554985 | X87: =R87/M87*100000 -> 30.528137 | Y87: =S87/N87*100000 -> 210.615 | Z87: =T87/N87*100000 -> 94.776748 | AA87: =AVERAGE(U87:Y87) -> 91.799644 | AB87: =MEDIAN(U87:Y87) -> 30.528137 | AC87: =IF(AB87=0,(Z87-0.01)/0.01,(Z87-AB87)/AB87) -> 2.1045703 | AD87: =COUNTIF(O87:S87,">0") -> 4 | AE87: =IF(AA87<50,1,IF(AA87<101,2,IF(AA87<151,3,IF(AA87<201,4,5)))) -> 2 | AF87: =IF(AC87<-50%,1,IF(AC87<-10%,2,IF(AC87<10%,3,IF(AC87<51%,4,5)))) -> 5 | AG87: =AD87+AE87+AF87 -> 11 | AH87: 99.181669 | AI87: 0.81833061 | AJ87: 95.17134 | AK87: 381.76067 | AL87: 378.2366 | AM87: 37.970009 | AN87: 306.41882 | AO87: 482.13196

Sheet ketinggian
A1: Desa | B1: _mean | C1: _median | D1: _stdev | E1: _min | F1: _max | I1: No | J1: kecamatan | K1: puskesmas | L1: desa | M1: ketinggian_mean | N1: ketinggian_median | O1: ketinggian_SD | P1: ketinggian_min | Q1: ketinggian_max
A2: Ambarketawang | B2: 98.852549 | C2: 98.015808 | D2: 9.355936 | E2: 76.702072 | F2: 135.8618 | I2: 1 | J2: BERBAH | K2: Berbah | L2: Kalitirto | M2: =VLOOKUP(L2,$A$2:$F$87,2,0) -> 106.62523 | N2: =VLOOKUP(L2,$A$2:$F$87,3,0) -> 106.98101 | O2: =VLOOKUP(L2,$A$2:$F$87,4,0) -> 9.0298578 | P2: =VLOOKUP(L2,$A$2:$F$87,5,0) -> 74.44146 | Q2: =VLOOKUP(L2,$A$2:$F$87,6,0) -> 128.71031
A3: Argomulyo | B3: 394.07111 | C3: 393.32678 | D3: 38.771007 | E3: 80.154503 | F3: 489.98975 | I3: 2 | J3: BERBAH | K3: Berbah | L3: Sendangtirto | M3: =VLOOKUP(L3,$A$2:$F$87,2,0) -> 88.824592 | N3: =VLOOKUP(L3,$A$2:$F$87,3,0) -> 89.240211 | O3: =VLOOKUP(L3,$A$2:$F$87,4,0) -> 7.3364995 | P3: =VLOOKUP(L3,$A$2:$F$87,5,0) -> 67.643204 | Q3: =VLOOKUP(L3,$A$2:$F$87,6,0) -> 110.91736
A4: Balecatur | B4: 102.55834 | C4: 96.937305 | D4: 16.847594 | E4: 75.061012 | F4: 172.50914 | I4: 3 | J4: BERBAH | K4: Berbah | L4: Tegaltirto | M4: =VLOOKUP(L4,$A$2:$F$87,2,0) -> 94.678601 | N4: =VLOOKUP(L4,$A$2:$F$87,3,0) -> 91.71563 | O4: =VLOOKUP(L4,$A$2:$F$87,4,0) -> 11.035832 | P4: =VLOOKUP(L4,$A$2:$F$87,5,0) -> 69.403664 | Q4: =VLOOKUP(L4,$A$2:$F$87,6,0) -> 123.96963
A5: Bangunkerto | B5: 413.75708 | C5: 403.58516 | D5: 61.569624 | E5: 318.9614 | F5: 568.63696 | I5: 4 | J5: BERBAH | K5: Berbah | L5: Jogotirto | M5: =VLOOKUP(L5,$A$2:$F$87,2,0) -> 95.544823 | N5: =VLOOKUP(L5,$A$2:$F$87,3,0) -> 94.460609 | O5: =VLOOKUP(L5,$A$2:$F$87,4,0) -> 8.5351184 | P5: =VLOOKUP(L5,$A$2:$F$87,5,0) -> 73.477081 | Q5: =VLOOKUP(L5,$A$2:$F$87,6,0) -> 140.70663
A6: Banyuraden | B6: 109.54466 | C6: 110.16756 | D6: 6.4786575 | E6: 87.274857 | F6: 126.16867 | I6: 5 | J6: CANGKRINGAN | K6: cangkringan | L6: Glagaharjo | M6: =VLOOKUP(L6,$A$2:$F$87,2,0) -> 825.8767 | N6: =VLOOKUP(L6,$A$2:$F$87,3,0) -> 778.81592 | O6: =VLOOKUP(L6,$A$2:$F$87,4,0) -> 245.51977 | P6: =VLOOKUP(L6,$A$2:$F$87,5,0) -> 462.74673 | Q6: =VLOOKUP(L6,$A$2:$F$87,6,0) -> 1398.238
A7: Banyurejo | B7: 160.12308 | C7: 161.6187 | D7: 16.070804 | E7: 102.96763 | F7: 199.88213 | I7: 6 | J7: CANGKRINGAN | K7: cangkringan | L7: Wukirsari | M7: =VLOOKUP(L7,$A$2:$F$87,2,0) -> 489.73962 | N7: =VLOOKUP(L7,$A$2:$F$87,3,0) -> 489.18585 | O7: =VLOOKUP(L7,$A$2:$F$87,4,0) -> 60.826609 | P7: =VLOOKUP(L7,$A$2:$F$87,5,0) -> 374.19681 | Q7: =VLOOKUP(L7,$A$2:$F$87,6,0) -> 641.31598
A8: Bimomartani | B8: 281.55361 | C8: 283.94542 | D8: 40.417718 | E8: 199.30885 | F8: 356.81128 | I8: 7 | J8: CANGKRINGAN | K8: cangkringan | L8: Kepuharjo | M8: =VLOOKUP(L8,$A$2:$F$87,2,0) -> 808.09605 | N8: =VLOOKUP(L8,$A$2:$F$87,3,0) -> 757.82526 | O8: =VLOOKUP(L8,$A$2:$F$87,4,0) -> 168.00882 | P8: =VLOOKUP(L8,$A$2:$F$87,5,0) -> 590.66223 | Q8: =VLOOKUP(L8,$A$2:$F$87,6,0) -> 1332.4939
A9: Bokoharjo | B9: 136.41391 | C9: 127.52158 | D9: 21.735899 | E9: 104.84348 | F9: 223.23006 | I9: 8 | J9: CANGKRINGAN | K9: cangkringan | L9: Umbulharjo | M9: =VLOOKUP(L9,$A$2:$F$87,2,0) -> 766.97109 | N9: =VLOOKUP(L9,$A$2:$F$87,3,0) -> 728.30261 | O9: =VLOOKUP(L9,$A$2:$F$87,4,0) -> 172.05657 | P9: =VLOOKUP(L9,$A$2:$F$87,5,0) -> 473.8732 | Q9: =VLOOKUP(L9,$A$2:$F$87,6,0) -> 1352.0422
A10: Candibinangun | B10: 442.81559 | C10: 435.02481 | D10: 80.638014 | E10: 313.40546 | F10: 610.77588 | I10: 9 | J10: CANGKRINGAN | K10: cangkringan | L10: Argomulyo | M10: =VLOOKUP(L10,$A$2:$F$87,2,0) -> 394.07111 | N10: =VLOOKUP(L10,$A$2:$F$87,3,0) -> 393.32678 | O10: =VLOOKUP(L10,$A$2:$F$87,4,0) -> 38.771007 | P10: =VLOOKUP(L10,$A$2:$F$87,5,0) -> 80.154503 | Q10: =VLOOKUP(L10,$A$2:$F$87,6,0) -> 489.98975
A11: Caturharjo | B11: 238.78151 | C11: 237.23949 | D11: 20.726219 | E11: 197.18819 | F11: 297.96204 | I11: 10 | J11: DEPOK | K11: Depok 1 | L11: Maguwoharjo | M11: =VLOOKUP(L11,$A$2:$F$87,2,0) -> 136.44325 | N11: =VLOOKUP(L11,$A$2:$F$87,3,0) -> 136.36624 | O11: =VLOOKUP(L11,$A$2:$F$87,4,0) -> 20.636666 | P11: =VLOOKUP(L11,$A$2:$F$87,5,0) -> 96.269791 | Q11: =VLOOKUP(L11,$A$2:$F$87,6,0) -> 182.85393
A12: Caturtunggal | B12: 135.33847 | C12: 134.08095 | D12: 11.119062 | E12: 106.4479 | F12: 168.57657 | I12: 11 | J12: DEPOK | K12: Depok 2 | L12: Condongcatur | M12: =VLOOKUP(L12,$A$2:$F$87,2,0) -> 161.40281 | N12: =VLOOKUP(L12,$A$2:$F$87,3,0) -> 160.34607 | O12: =VLOOKUP(L12,$A$2:$F$87,4,0) -> 15.498034 | P12: =VLOOKUP(L12,$A$2:$F$87,5,0) -> 121.12942 | Q12: =VLOOKUP(L12,$A$2:$F$87,6,0) -> 207.93137
A13: Condongcatur | B13: 161.40281 | C13: 160.34607 | D13: 15.498034 | E13: 121.12942 | F13: 207.93137 | I13: 12 | J13: DEPOK | K13: Depok 3 | L13: Caturtunggal | M13: =VLOOKUP(L13,$A$2:$F$87,2,0) -> 135.33847 | N13: =VLOOKUP(L13,$A$2:$F$87,3,0) -> 134.08095 | O13: =VLOOKUP(L13,$A$2:$F$87,4,0) -> 11.119062 | P13: =VLOOKUP(L13,$A$2:$F$87,5,0) -> 106.4479 | Q13: =VLOOKUP(L13,$A$2:$F$87,6,0) -> 168.57657
... A87: Wukirsari | B87: 489.73962 | C87: 489.18585 | D87: 60.826609 | E87: 374.19681 | F87: 641.31598 | I87: 86 | J87: TURI | K87: turi | L87: Donokerto | M87: =VLOOKUP(L87,$A$2:$F$87,2,0) -> 381.76067 | N87: =VLOOKUP(L87,$A$2:$F$87,3,0) -> 378.2366 | O87: =VLOOKUP(L87,$A$2:$F$87,4,0) -> 37.970009 | P87: =VLOOKUP(L87,$A$2:$F$87,5,0) -> 306.41882 | Q87: =VLOOKUP(L87,$A$2:$F$87,6,0) -> 482.13196

Sheet temporal
A1: id_desa | B1: puskesmas | C1: desa | D1: Kategori | E1: Status Intervensi | F1: tanggal | G1: bulan | H1: tahun | I1: DBD | J1: DD | K1: Infeksi Dengue | L1: Penduduk | M1: IR DBD | N1: IR DD | O1: IR dengue | P1: ABJ | Q1: covid
A2: =_xlfn.XLOOKUP(C2,kamus!$B$2:$B$87,kamus!$A$2:$A$87,0,0,1) -> 4 | B2: =_xlfn.XLOOKUP(C2,kamus!$B$2:$B$87,kamus!$D$2:$D$87,"dihapus",0,1) -> Berbah | C2: jogotirto | D2: =_xlfn.XLOOKUP(C2,kamus!$B$2:$B$87,kamus!$J$2:$J$87,"dihapus",0,1) -> 0 | E2: =IF(D2=0,0,IF(H2<2021,0,IF(AND(H2=2021,G2<5),0,1))) -> 0 | F2: 42370 | G2: =MONTH(F2) -> 1 | H2: =YEAR(F2) -> 2016 | I2: 2 | K2: =J2+I2 -> 2 | L2: 11448 | M2: =IF(ISBLANK(I2)=TRUE,"",I2/$L2*100000) -> 17.4703 | N2: =IF(ISBLANK(J2)=TRUE,"",J2/$L2*100000) | O2: =IF(ISBLANK(K2)=TRUE,"",K2/$L2*100000) -> 17.4703 | Q2: =_xlfn.XLOOKUP(C2&G2&H2,covid!$E$2:$E$2184,covid!$D$2:$D$2184,0,0,1) -> 0
A3: =_xlfn.XLOOKUP(C3,kamus!$B$2:$B$87,kamus!$A$2:$A$87,0,0,1) -> 1 | B3: =_xlfn.XLOOKUP(C3,kamus!$B$2:$B$87,kamus!$D$2:$D$87,"dihapus",0,1) -> Berbah | C3: kalitirto | D3: =_xlfn.XLOOKUP(C3,kamus!$B$2:$B$87,kamus!$J$2:$J$87,"dihapus",0,1) -> 1 | E3: =IF(D3=0,0,IF(H3<2021,0,IF(AND(H3=2021,G3<5),0,1))) -> 0 | F3: 42370 | G3: =MONTH(F3) -> 1 | H3: =YEAR(F3) -> 2016 | I3: 4 | K3: =J3+I3 -> 4 | L3: 14565 | M3: =IF(ISBLANK(I3)=TRUE,"",I3/$L3*100000) -> 27.463096 | N3: =IF(ISBLANK(J3)=TRUE,"",J3/$L3*100000) | O3: =IF(ISBLANK(K3)=TRUE,"",K3/$L3*100000) -> 27.463096 | Q3: =_xlfn.XLOOKUP(C3&G3&H3,covid!$E$2:$E$2184,covid!$D$2:$D$2184,0,0,1) -> 0
A4: =_xlfn.XLOOKUP(C4,kamus!$B$2:$B$87,kamus!$A$2:$A$87,0,0,1) -> 2 | B4: =_xlfn.XLOOKUP(C4,kamus!$B$2:$B$87,kamus!$D$2:$D$87,"dihapus",0,1) -> Berbah | C4: sendangtirto | D4: =_xlfn.XLOOKUP(C4,kamus!$B$2:$B$87,kamus!$J$2:$J$87,"dihapus",0,1) -> 1 | E4: =IF(D4=0,0,IF(H4<2021,0,IF(AND(H4=2021,G4<5),0,1))) -> 0 | F4: 42370 | G4: =MONTH(F4) -> 1 | H4: =YEAR(F4) -> 2016 | I4: 0 | K4: =J4+I4 -> 0 | L4: 18704 | M4: =IF(ISBLANK(I4)=TRUE,"",I4/$L4*100000) -> 0 | N4: =IF(ISBLANK(J4)=TRUE,"",J4/$L4*100000) | O4: =IF(ISBLANK(K4)=TRUE,"",K4/$L4*100000) -> 0 | Q4: =_xlfn.XLOOKUP(C4&G4&H4,covid!$E$2:$E$2184,covid!$D$2:$D$2184,0,0,1) -> 0
A5: =_xlfn.XLOOKUP(C5,kamus!$B$2:$B$87,kamus!$A$2:$A$87,0,0,1) -> 3 | B5: =_xlfn.XLOOKUP(C5,kamus!$B$2:$B$87,kamus!$D$2:$D$87,"dihapus",0,1) -> Berbah | C5: tegaltirto | D5: =_xlfn.XLOOKUP(C5,kamus!$B$2:$B$87,kamus!$J$2:$J$87,"dihapus",0,1) -> 1 | E5: =IF(D5=0,0,IF(H5<2021,0,IF(AND(H5=2021,G5<5),0,1))) -> 0 | F5: 42370 | G5: =MONTH(F5) -> 1 | H5: =YEAR(F5) -> 2016 | I5: 0 | K5: =J5+I5 -> 0 | L5: 13363 | M5: =IF(ISBLANK(I5)=TRUE,"",I5/$L5*100000) -> 0 | N5: =IF(ISBLANK(J5)=TRUE,"",J5/$L5*100000) | O5: =IF(ISBLANK(K5)=TRUE,"",K5/$L5*100000) -> 0 | Q5: =_xlfn.XLOOKUP(C5&G5&H5,covid!$E$2:$E$2184,covid!$D$2:$D$2184,0,0,1) -> 0
A6: =_xlfn.XLOOKUP(C6,kamus!$B$2:$B$87,kamus!$A$2:$A$87,0,0,1) -> 9 | B6: =_xlfn.XLOOKUP(C6,kamus!$B$2:$B$87,kamus!$D$2:$D$87,"dihapus",0,1) -> cangkringan | C6: argomulyo | D6: =_xlfn.XLOOKUP(C6,kamus!$B$2:$B$87,kamus!$J$2:$J$87,"dihapus",0,1) -> 0 | E6: =IF(D6=0,0,IF(H6<2021,0,IF(AND(H6=2021,G6<5),0,1))) -> 0 | F6: 42370 | G6: =MONTH(F6) -> 1 | H6: =YEAR(F6) -> 2016 | I6: 0 | K6: =J6+I6 -> 0 | L6: 8063 | M6: =IF(ISBLANK(I6)=TRUE,"",I6/$L6*100000) -> 0 | N6: =IF(ISBLANK(J6)=TRUE,"",J6/$L6*100000) | O6: =IF(ISBLANK(K6)=TRUE,"",K6/$L6*100000) -> 0 | Q6: =_xlfn.XLOOKUP(C6&G6&H6,covid!$E$2:$E$2184,covid!$D$2:$D$2184,0,0,1) -> 0
A7: =_xlfn.XLOOKUP(C7,kamus!$B$2:$B$87,kamus!$A$2:$A$87,0,0,1) -> 5 | B7: =_xlfn.XLOOKUP(C7,kamus!$B$2:$B$87,kamus!$D$2:$D$87,"dihapus",0,1) -> cangkringan | C7: glagaharjo | D7: =_xlfn.XLOOKUP(C7,kamus!$B$2:$B$87,kamus!$J$2:$J$87,"dihapus",0,1) -> 0 | E7: =IF(D7=0,0,IF(H7<2021,0,IF(AND(H7=2021,G7<5),0,1))) -> 0 | F7: 42370 | G7: =MONTH(F7) -> 1 | H7: =YEAR(F7) -> 2016 | I7: 0 | K7: =J7+I7 -> 0 | L7: 4133 | M7: =IF(ISBLANK(I7)=TRUE,"",I7/$L7*100000) -> 0 | N7: =IF(ISBLANK(J7)=TRUE,"",J7/$L7*100000) | O7: =IF(ISBLANK(K7)=TRUE,"",K7/$L7*100000) -> 0 | Q7: =_xlfn.XLOOKUP(C7&G7&H7,covid!$E$2:$E$2184,covid!$D$2:$D$2184,0,0,1) -> 0
A8: =_xlfn.XLOOKUP(C8,kamus!$B$2:$B$87,kamus!$A$2:$A$87,0,0,1) -> 7 | B8: =_xlfn.XLOOKUP(C8,kamus!$B$2:$B$87,kamus!$D$2:$D$87,"dihapus",0,1) -> cangkringan | C8: kepuharjo | D8: =_xlfn.XLOOKUP(C8,kamus!$B$2:$B$87,kamus!$J$2:$J$87,"dihapus",0,1) -> 0 | E8: =IF(D8=0,0,IF(H8<2021,0,IF(AND(H8=2021,G8<5),0,1))) -> 0 | F8: 42370 | G8: =MONTH(F8) -> 1 | H8: =YEAR(F8) -> 2016 | I8: 0 | K8: =J8+I8 -> 0 | L8: 3586 | M8: =IF(ISBLANK(I8)=TRUE,"",I8/$L8*100000) -> 0 | N8: =IF(ISBLANK(J8)=TRUE,"",J8/$L8*100000) | O8: =IF(ISBLANK(K8)=TRUE,"",K8/$L8*100000) -> 0 | Q8: =_xlfn.XLOOKUP(C8&G8&H8,covid!$E$2:$E$2184,covid!$D$2:$D$2184,0,0,1) -> 0
A9: =_xlfn.XLOOKUP(C9,kamus!$B$2:$B$87,kamus!$A$2:$A$87,0,0,1) -> 8 | B9: =_xlfn.XLOOKUP(C9,kamus!$B$2:$B$87,kamus!$D$2:$D$87,"dihapus",0,1) -> cangkringan | C9: umbulharjo | D9: =_xlfn.XLOOKUP(C9,kamus!$B$2:$B$87,kamus!$J$2:$J$87,"dihapus",0,1) -> 0 | E9: =IF(D9=0,0,IF(H9<2021,0,IF(AND(H9=2021,G9<5),0,1))) -> 0 | F9: 42370 | G9: =MONTH(F9) -> 1 | H9: =YEAR(F9) -> 2016 | I9: 0 | K9: =J9+I9 -> 0 | L9: 5550 | M9: =IF(ISBLANK(I9)=TRUE,"",I9/$L9*100000) -> 0 | N9: =IF(ISBLANK(J9)=TRUE,"",J9/$L9*100000) | O9: =IF(ISBLANK(K9)=TRUE,"",K9/$L9*100000) -> 0 | Q9: =_xlfn.XLOOKUP(C9&G9&H9,covid!$E$2:$E$2184,covid!$D$2:$D$2184,0,0,1) -> 0
A10: =_xlfn.XLOOKUP(C10,kamus!$B$2:$B$87,kamus!$A$2:$A$87,0,0,1) -> 6 | B10: =_xlfn.XLOOKUP(C10,kamus!$B$2:$B$87,kamus!$D$2:$D$87,"dihapus",0,1) -> cangkringan | C10: wukirsari | D10: =_xlfn.XLOOKUP(C10,kamus!$B$2:$B$87,kamus!$J$2:$J$87,"dihapus",0,1) -> 0 | E10: =IF(D10=0,0,IF(H10<2021,0,IF(AND(H10=2021,G10<5),0,1))) -> 0 | F10: 42370 | G10: =MONTH(F10) -> 1 | H10: =YEAR(F10) -> 2016 | I10: 0 | K10: =J10+I10 -> 0 | L10: 11339 | M10: =IF(ISBLANK(I10)=TRUE,"",I10/$L10*100000) -> 0 | N10: =IF(ISBLANK(J10)=TRUE,"",J10/$L10*100000) | O10: =IF(ISBLANK(K10)=TRUE,"",K10/$L10*100000) -> 0 | Q10: =_xlfn.XLOOKUP(C10&G10&H10,covid!$E$2:$E$2184,covid!$D$2:$D$2184,0,0,1) -> 0
A11: =_xlfn.XLOOKUP(C11,kamus!$B$2:$B$87,kamus!$A$2:$A$87,0,0,1) -> 10 | B11: =_xlfn.XLOOKUP(C11,kamus!$B$2:$B$87,kamus!$D$2:$D$87,"dihapus",0,1) -> Depok 1 | C11: maguwoharjo | D11: =_xlfn.XLOOKUP(C11,kamus!$B$2:$B$87,kamus!$J$2:$J$87,"dihapus",0,1) -> 1 | E11: =IF(D11=0,0,IF(H11<2021,0,IF(AND(H11=2021,G11<5),0,1))) -> 0 | F11: 42370 | G11: =MONTH(F11) -> 1 | H11: =YEAR(F11) -> 2016 | I11: 9 | K11: =J11+I11 -> 9 | L11: 37946 | M11: =IF(ISBLANK(I11)=TRUE,"",I11/$L11*100000) -> 23.717915 | N11: =IF(ISBLANK(J11)=TRUE,"",J11/$L11*100000) | O11: =IF(ISBLANK(K11)=TRUE,"",K11/$L11*100000) -> 23.717915 | Q11: =_xlfn.XLOOKUP(C11&G11&H11,covid!$E$2:$E$2184,covid!$D$2:$D$2184,0,0,1) -> 0
A12: =_xlfn.XLOOKUP(C12,kamus!$B$2:$B$87,kamus!$A$2:$A$87,0,0,1) -> 11 | B12: =_xlfn.XLOOKUP(C12,kamus!$B$2:$B$87,kamus!$D$2:$D$87,"dihapus",0,1) -> Depok 2 | C12: condongcatur | D12: =_xlfn.XLOOKUP(C12,kamus!$B$2:$B$87,kamus!$J$2:$J$87,"dihapus",0,1) -> 1 | E12: =IF(D12=0,0,IF(H12<2021,0,IF(AND(H12=2021,G12<5),0,1))) -> 0 | F12: 42370 | G12: =MONTH(F12) -> 1 | H12: =YEAR(F12) -> 2016 | I12: 2 | K12: =J12+I12 -> 2 | L12: 44433 | M12: =IF(ISBLANK(I12)=TRUE,"",I12/$L12*100000) -> 4.501159 | N12: =IF(ISBLANK(J12)=TRUE,"",J12/$L12*100000) | O12: =IF(ISBLANK(K12)=TRUE,"",K12/$L12*100000) -> 4.501159 | Q12: =_xlfn.XLOOKUP(C12&G12&H12,covid!$E$2:$E$2184,covid!$D$2:$D$2184,0,0,1) -> 0
A13: =_xlfn.XLOOKUP(C13,kamus!$B$2:$B$87,kamus!$A$2:$A$87,0,0,1) -> 12 | B13: =_xlfn.XLOOKUP(C13,kamus!$B$2:$B$87,kamus!$D$2:$D$87,"dihapus",0,1) -> Depok 3 | C13: caturtunggal | D13: =_xlfn.XLOOKUP(C13,kamus!$B$2:$B$87,kamus!$J$2:$J$87,"dihapus",0,1) -> 1 | E13: =IF(D13=0,0,IF(H13<2021,0,IF(AND(H13=2021,G13<5),0,1))) -> 0 | F13: 42370 | G13: =MONTH(F13) -> 1 | H13: =YEAR(F13) -> 2016 | I13: 8 | K13: =J13+I13 -> 8 | L13: 44837 | M13: =IF(ISBLANK(I13)=TRUE,"",I13/$L13*100000) -> 17.842407 | N13: =IF(ISBLANK(J13)=TRUE,"",J13/$L13*100000) | O13: =IF(ISBLANK(K13)=TRUE,"",K13/$L13*100000) -> 17.842407 | Q13: =_xlfn.XLOOKUP(C13&G13&H13,covid!$E$2:$E$2184,covid!$D$2:$D$2184,0,0,1) -> 0
A14: =_xlfn.XLOOKUP(C14,kamus!$B$2:$B$87,kamus!$A$2:$A$87,0,0,1) -> 0 | B14: =_xlfn.XLOOKUP(C14,kamus!$B$2:$B$87,kamus!$D$2:$D$87,"dihapus",0,1) -> dihapus | C14: z_desa tidak diketahui | D14: =_xlfn.XLOOKUP(C14,kamus!$B$2:$B$87,kamus!$J$2:$J$87,"dihapus",0,1) -> dihapus | E14: =IF(D14=0,0,IF(H14<2021,0,IF(AND(H14=2021,G14<5),0,1))) -> 0 | F14: 42370 | G14: =MONTH(F14) -> 1 | H14: =YEAR(F14) -> 2016 | I14: 0 | K14: =J14+I14 -> 0 | L14: #N/A | M14: =IF(ISBLANK(I14)=TRUE,"",I14/$L14*100000) -> #N/A | N14: =IF(ISBLANK(J14)=TRUE,"",J14/$L14*100000) | O14: =IF(ISBLANK(K14)=TRUE,"",K14/$L14*100000) -> #N/A | Q14: =_xlfn.XLOOKUP(C14&G14&H14,covid!$E$2:$E$2184,covid!$D$2:$D$2184,0,0,1) -> 0
A15: =_xlfn.XLOOKUP(C15,kamus!$B$2:$B$87,kamus!$A$2:$A$87,0,0,1) -> 14 | B15: =_xlfn.XLOOKUP(C15,kamus!$B$2:$B$87,kamus!$D$2:$D$87,"dihapus",0,1) -> Gamping 1 | C15: ambarketawang | D15: =_xlfn.XLOOKUP(C15,kamus!$B$2:$B$87,kamus!$J$2:$J$87,"dihapus",0,1) -> 1 | E15: =IF(D15=0,0,IF(H15<2021,0,IF(AND(H15=2021,G15<5),0,1))) -> 0 | F15: 42370 | G15: =MONTH(F15) -> 1 | H15: =YEAR(F15) -> 2016 | I15: 6 | K15: =J15+I15 -> 6 | L15: 22819 | M15: =IF(ISBLANK(I15)=TRUE,"",I15/$L15*100000) -> 26.293878 | N15: =IF(ISBLANK(J15)=TRUE,"",J15/$L15*100000) | O15: =IF(ISBLANK(K15)=TRUE,"",K15/$L15*100000) -> 26.293878 | Q15: =_xlfn.XLOOKUP(C15&G15&H15,covid!$E$2:$E$2184,covid!$D$2:$D$2184,0,0,1) -> 0
A16: =_xlfn.XLOOKUP(C16,kamus!$B$2:$B$87,kamus!$A$2:$A$87,0,0,1) -> 13 | B16: =_xlfn.XLOOKUP(C16,kamus!$B$2:$B$87,kamus!$D$2:$D$87,"dihapus",0,1) -> Gamping 1 | C16: balecatur | D16: =_xlfn.XLOOKUP(C16,kamus!$B$2:$B$87,kamus!$J$2:$J$87,"dihapus",0,1) -> 1 | E16: =IF(D16=0,0,IF(H16<2021,0,IF(AND(H16=2021,G16<5),0,1))) -> 0 | F16: 42370 | G16: =MONTH(F16) -> 1 | H16: =YEAR(F16) -> 2016 | I16: 0 | K16: =J16+I16 -> 0 | L16: 20645 | M16: =IF(ISBLANK(I16)=TRUE,"",I16/$L16*100000) -> 0 | N16: =IF(ISBLANK(J16)=TRUE,"",J16/$L16*100000) | O16: =IF(ISBLANK(K16)=TRUE,"",K16/$L16*100000) -> 0 | Q16: =_xlfn.XLOOKUP(C16&G16&H16,covid!$E$2:$E$2184,covid!$D$2:$D$2184,0,0,1) -> 0
A17: =_xlfn.XLOOKUP(C17,kamus!$B$2:$B$87,kamus!$A$2:$A$87,0,0,1) -> 16 | B17: =_xlfn.XLOOKUP(C17,kamus!$B$2:$B$87,kamus!$D$2:$D$87,"dihapus",0,1) -> Gamping 2 | C17: banyuraden | D17: =_xlfn.XLOOKUP(C17,kamus!$B$2:$B$87,kamus!$J$2:$J$87,"dihapus",0,1) -> 1 | E17: =IF(D17=0,0,IF(H17<2021,0,IF(AND(H17=2021,G17<5),0,1))) -> 0 | F17: 42370 | G17: =MONTH(F17) -> 1 | H17: =YEAR(F17) -> 2016 | I17: 1 | K17: =J17+I17 -> 1 | L17: 16624 | M17: =IF(ISBLANK(I17)=TRUE,"",I17/$L17*100000) -> 6.0153994 | N17: =IF(ISBLANK(J17)=TRUE,"",J17/$L17*100000) | O17: =IF(ISBLANK(K17)=TRUE,"",K17/$L17*100000) -> 6.0153994 | Q17: =_xlfn.XLOOKUP(C17&G17&H17,covid!$E$2:$E$2184,covid!$D$2:$D$2184,0,0,1) -> 0
A18: =_xlfn.XLOOKUP(C18,kamus!$B$2:$B$87,kamus!$A$2:$A$87,0,0,1) -> 15 | B18: =_xlfn.XLOOKUP(C18,kamus!$B$2:$B$87,kamus!$D$2:$D$87,"dihapus",0,1) -> Gamping 2 | C18: nogotirto | D18: =_xlfn.XLOOKUP(C18,kamus!$B$2:$B$87,kamus!$J$2:$J$87,"dihapus",0,1) -> 1 | E18: =IF(D18=0,0,IF(H18<2021,0,IF(AND(H18=2021,G18<5),0,1))) -> 0 | F18: 42370 | G18: =MONTH(F18) -> 1 | H18: =YEAR(F18) -> 2016 | I18: 1 | K18: =J18+I18 -> 1 | L18: 18692 | M18: =IF(ISBLANK(I18)=TRUE,"",I18/$L18*100000) -> 5.3498823 | N18: =IF(ISBLANK(J18)=TRUE,"",J18/$L18*100000) | O18: =IF(ISBLANK(K18)=TRUE,"",K18/$L18*100000) -> 5.3498823 | Q18: =_xlfn.XLOOKUP(C18&G18&H18,covid!$E$2:$E$2184,covid!$D$2:$D$2184,0,0,1) -> 0
A19: =_xlfn.XLOOKUP(C19,kamus!$B$2:$B$87,kamus!$A$2:$A$87,0,0,1) -> 17 | B19: =_xlfn.XLOOKUP(C19,kamus!$B$2:$B$87,kamus!$D$2:$D$87,"dihapus",0,1) -> Gamping 2 | C19: trihanggo | D19: =_xlfn.XLOOKUP(C19,kamus!$B$2:$B$87,kamus!$J$2:$J$87,"dihapus",0,1) -> 1 | E19: =IF(D19=0,0,IF(H19<2021,0,IF(AND(H19=2021,G19<5),0,1))) -> 0 | F19: 42370 | G19: =MONTH(F19) -> 1 | H19: =YEAR(F19) -> 2016 | I19: 0 | K19: =J19+I19 -> 0 | L19: 18667 | M19: =IF(ISBLANK(I19)=TRUE,"",I19/$L19*100000) -> 0 | N19: =IF(ISBLANK(J19)=TRUE,"",J19/$L19*100000) | O19: =IF(ISBLANK(K19)=TRUE,"",K19/$L19*100000) -> 0 | Q19: =_xlfn.XLOOKUP(C19&G19&H19,covid!$E$2:$E$2184,covid!$D$2:$D$2184,0,0,1) -> 0
A20: =_xlfn.XLOOKUP(C20,kamus!$B$2:$B$87,kamus!$A$2:$A$87,0,0,1) -> 20 | B20: =_xlfn.XLOOKUP(C20,kamus!$B$2:$B$87,kamus!$D$2:$D$87,"dihapus",0,1) -> Godean 1 | C20: sidoagung | D20: =_xlfn.XLOOKUP(C20,kamus!$B$2:$B$87,kamus!$J$2:$J$87,"dihapus",0,1) -> 1 | E20: =IF(D20=0,0,IF(H20<2021,0,IF(AND(H20=2021,G20<5),0,1))) -> 0 | F20: 42370 | G20: =MONTH(F20) -> 1 | H20: =YEAR(F20) -> 2016 | I20: 9 | K20: =J20+I20 -> 9 | L20: 9743 | M20: =IF(ISBLANK(I20)=TRUE,"",I20/$L20*100000) -> 92.374012 | N20: =IF(ISBLANK(J20)=TRUE,"",J20/$L20*100000) | O20: =IF(ISBLANK(K20)=TRUE,"",K20/$L20*100000) -> 92.374012 | Q20: =_xlfn.XLOOKUP(C20&G20&H20,covid!$E$2:$E$2184,covid!$D$2:$D$2184,0,0,1) -> 0
A21: =_xlfn.XLOOKUP(C21,kamus!$B$2:$B$87,kamus!$A$2:$A$87,0,0,1) -> 21 | B21: =_xlfn.XLOOKUP(C21,kamus!$B$2:$B$87,kamus!$D$2:$D$87,"dihapus",0,1) -> Godean 1 | C21: sidoluhur | D21: =_xlfn.XLOOKUP(C21,kamus!$B$2:$B$87,kamus!$J$2:$J$87,"dihapus",0,1) -> 1 | E21: =IF(D21=0,0,IF(H21<2021,0,IF(AND(H21=2021,G21<5),0,1))) -> 0 | F21: 42370 | G21: =MONTH(F21) -> 1 | H21: =YEAR(F21) -> 2016 | I21: 0 | K21: =J21+I21 -> 0 | L21: 10269 | M21: =IF(ISBLANK(I21)=TRUE,"",I21/$L21*100000) -> 0 | N21: =IF(ISBLANK(J21)=TRUE,"",J21/$L21*100000) | O21: =IF(ISBLANK(K21)=TRUE,"",K21/$L21*100000) -> 0 | Q21: =_xlfn.XLOOKUP(C21&G21&H21,covid!$E$2:$E$2184,covid!$D$2:$D$2184,0,0,1) -> 0
A22: =_xlfn.XLOOKUP(C22,kamus!$B$2:$B$87,kamus!$A$2:$A$87,0,0,1) -> 19 | B22: =_xlfn.XLOOKUP(C22,kamus!$B$2:$B$87,kamus!$D$2:$D$87,"dihapus",0,1) -> Godean 1 | C22: sidomoyo | D22: =_xlfn.XLOOKUP(C22,kamus!$B$2:$B$87,kamus!$J$2:$J$87,"dihapus",0,1) -> 1 | E22: =IF(D22=0,0,IF(H22<2021,0,IF(AND(H22=2021,G22<5),0,1))) -> 0 | F22: 42370 | G22: =MONTH(F22) -> 1 | H22: =YEAR(F22) -> 2016 | I22: 0 | K22: =J22+I22 -> 0 | L22: 9159 | M22: =IF(ISBLANK(I22)=TRUE,"",I22/$L22*100000) -> 0 | N22: =IF(ISBLANK(J22)=TRUE,"",J22/$L22*100000) | O22: =IF(ISBLANK(K22)=TRUE,"",K22/$L22*100000) -> 0 | Q22: =_xlfn.XLOOKUP(C22&G22&H22,covid!$E$2:$E$2184,covid!$D$2:$D$2184,0,0,1) -> 0
A23: =_xlfn.XLOOKUP(C23,kamus!$B$2:$B$87,kamus!$A$2:$A$87,0,0,1) -> 18 | B23: =_xlfn.XLOOKUP(C23,kamus!$B$2:$B$87,kamus!$D$2:$D$87,"dihapus",0,1) -> Godean 1 | C23: sidomulyo | D23: =_xlfn.XLOOKUP(C23,kamus!$B$2:$B$87,kamus!$J$2:$J$87,"dihapus",0,1) -> 0 | E23: =IF(D23=0,0,IF(H23<2021,0,IF(AND(H23=2021,G23<5),0,1))) -> 0 | F23: 42370 | G23: =MONTH(F23) -> 1 | H23: =YEAR(F23) -> 2016 | I23: 1 | K23: =J23+I23 -> 1 | L23: 6607 | M23: =IF(ISBLANK(I23)=TRUE,"",I23/$L23*100000) -> 15.135462 | N23: =IF(ISBLANK(J23)=TRUE,"",J23/$L23*100000) | O23: =IF(ISBLANK(K23)=TRUE,"",K23/$L23*100000) -> 15.135462 | Q23: =_xlfn.XLOOKUP(C23&G23&H23,covid!$E$2:$E$2184,covid!$D$2:$D$2184,0,0,1) -> 0
A24: =_xlfn.XLOOKUP(C24,kamus!$B$2:$B$87,kamus!$A$2:$A$87,0,0,1) -> 23 | B24: =_xlfn.XLOOKUP(C24,kamus!$B$2:$B$87,kamus!$D$2:$D$87,"dihapus",0,1) -> Godean 2 | C24: sidoarum | D24: =_xlfn.XLOOKUP(C24,kamus!$B$2:$B$87,kamus!$J$2:$J$87,"dihapus",0,1) -> 1 | E24: =IF(D24=0,0,IF(H24<2021,0,IF(AND(H24=2021,G24<5),0,1))) -> 0 | F24: 42370 | G24: =MONTH(F24) -> 1 | H24: =YEAR(F24) -> 2016 | I24: 2 | K24: =J24+I24 -> 2 | L24: 17439 | M24: =IF(ISBLANK(I24)=TRUE,"",I24/$L24*100000) -> 11.468548 | N24: =IF(ISBLANK(J24)=TRUE,"",J24/$L24*100000) | O24: =IF(ISBLANK(K24)=TRUE,"",K24/$L24*100000) -> 11.468548 | Q24: =_xlfn.XLOOKUP(C24&G24&H24,covid!$E$2:$E$2184,covid!$D$2:$D$2184,0,0,1) -> 0
A25: =_xlfn.XLOOKUP(C25,kamus!$B$2:$B$87,kamus!$A$2:$A$87,0,0,1) -> 22 | B25: =_xlfn.XLOOKUP(C25,kamus!$B$2:$B$87,kamus!$D$2:$D$87,"dihapus",0,1) -> Godean 2 | C25: sidokarto | D25: =_xlfn.XLOOKUP(C25,kamus!$B$2:$B$87,kamus!$J$2:$J$87,"dihapus",0,1) -> 1 | E25: =IF(D25=0,0,IF(H25<2021,0,IF(AND(H25=2021,G25<5),0,1))) -> 0 | F25: 42370 | G25: =MONTH(F25) -> 1 | H25: =YEAR(F25) -> 2016 | I25: 0 | K25: =J25+I25 -> 0 | L25: 12380 | M25: =IF(ISBLANK(I25)=TRUE,"",I25/$L25*100000) -> 0 | N25: =IF(ISBLANK(J25)=TRUE,"",J25/$L25*100000) | O25: =IF(ISBLANK(K25)=TRUE,"",K25/$L25*100000) -> 0 | Q25: =_xlfn.XLOOKUP(C25&G25&H25,covid!$E$2:$E$2184,covid!$D$2:$D$2184,0,0,1) -> 0
A26: =_xlfn.XLOOKUP(C26,kamus!$B$2:$B$87,kamus!$A$2:$A$87,0,0,1) -> 24 | B26: =_xlfn.XLOOKUP(C26,kamus!$B$2:$B$87,kamus!$D$2:$D$87,"dihapus",0,1) -> Godean 2 | C26: sidorejo | D26: =_xlfn.XLOOKUP(C26,kamus!$B$2:$B$87,kamus!$J$2:$J$87,"dihapus",0,1) -> 0 | E26: =IF(D26=0,0,IF(H26<2021,0,IF(AND(H26=2021,G26<5),0,1))) -> 0 | F26: 42370 | G26: =MONTH(F26) -> 1 | H26: =YEAR(F26) -> 2016 | I26: 1 | K26: =J26+I26 -> 1 | L26: 7087 | M26: =IF(ISBLANK(I26)=TRUE,"",I26/$L26*100000) -> 14.110343 | N26: =IF(ISBLANK(J26)=TRUE,"",J26/$L26*100000) | O26: =IF(ISBLANK(K26)=TRUE,"",K26/$L26*100000) -> 14.110343 | Q26: =_xlfn.XLOOKUP(C26&G26&H26,covid!$E$2:$E$2184,covid!$D$2:$D$2184,0,0,1) -> 0
... A100: =_xlfn.XLOOKUP(C100,kamus!$B$2:$B$87,kamus!$A$2:$A$87,0,0,1) -> 12 | B100: =_xlfn.XLOOKUP(C100,kamus!$B$2:$B$87,kamus!$D$2:$D$87,"dihapus",0,1) -> Depok 3 | C100: caturtunggal | D100: =_xlfn.XLOOKUP(C100,kamus!$B$2:$B$87,kamus!$J$2:$J$87,"dihapus",0,1) -> 1 | E100: =IF(D100=0,0,IF(H100<2021,0,IF(AND(H100=2021,G100<5),0,1))) -> 0 | F100: 42401 | G100: =MONTH(F100) -> 2 | H100: =YEAR(F100) -> 2016 | I100: 3 | K100: =J100+I100 -> 3 | L100: 44837 | M100: =IF(ISBLANK(I100)=TRUE,"",I100/$L100*100000) -> 6.6909026 | N100: =IF(ISBLANK(J100)=TRUE,"",J100/$L100*100000) | O100: =IF(ISBLANK(K100)=TRUE,"",K100/$L100*100000) -> 6.6909026 | Q100: =_xlfn.XLOOKUP(C100&G100&H100,covid!$E$2:$E$2184,covid!$D$2:$D$2184,0,0,1) -> 0
A101: =_xlfn.XLOOKUP(C101,kamus!$B$2:$B$87,kamus!$A$2:$A$87,0,0,1) -> 0 | B101: =_xlfn.XLOOKUP(C101,kamus!$B$2:$B$87,kamus!$D$2:$D$87,"dihapus",0,1) -> dihapus | C101: z_desa tidak diketahui | D101: =_xlfn.XLOOKUP(C101,kamus!$B$2:$B$87,kamus!$J$2:$J$87,"dihapus",0,1) -> dihapus | E101: =IF(D101=0,0,IF(H101<2021,0,IF(AND(H101=2021,G101<5),0,1))) -> 0 | F101: 42401 | G101: =MONTH(F101) -> 2 | H101: =YEAR(F101) -> 2016 | I101: 1 | K101: =J101+I101 -> 1 | L101: #N/A | M101: =IF(ISBLANK(I101)=TRUE,"",I101/$L101*100000) -> #N/A | N101: =IF(ISBLANK(J101)=TRUE,"",J101/$L101*100000) | O101: =IF(ISBLANK(K101)=TRUE,"",K101/$L101*100000) -> #N/A | Q101: =_xlfn.XLOOKUP(C101&G101&H101,covid!$E$2:$E$2184,covid!$D$2:$D$2184,0,0,1) -> 0
A102: =_xlfn.XLOOKUP(C102,kamus!$B$2:$B$87,kamus!$A$2:$A$87,0,0,1) -> 14 | B102: =_xlfn.XLOOKUP(C102,kamus!$B$2:$B$87,kamus!$D$2:$D$87,"dihapus",0,1) -> Gamping 1 | C102: ambarketawang | D102: =_xlfn.XLOOKUP(C102,kamus!$B$2:$B$87,kamus!$J$2:$J$87,"dihapus",0,1) -> 1 | E102: =IF(D102=0,0,IF(H102<2021,0,IF(AND(H102=2021,G102<5),0,1))) -> 0 | F102: 42401 | G102: =MONTH(F102) -> 2 | H102: =YEAR(F102) -> 2016 | I102: 9 | K102: =J102+I102 -> 9 | L102: 22819 | M102: =IF(ISBLANK(I102)=TRUE,"",I102/$L102*100000) -> 39.440817 | N102: =IF(ISBLANK(J102)=TRUE,"",J102/$L102*100000) | O102: =IF(ISBLANK(K102)=TRUE,"",K102/$L102*100000) -> 39.440817 | Q102: =_xlfn.XLOOKUP(C102&G102&H102,covid!$E$2:$E$2184,covid!$D$2:$D$2184,0,0,1) -> 0
A103: =_xlfn.XLOOKUP(C103,kamus!$B$2:$B$87,kamus!$A$2:$A$87,0,0,1) -> 13 | B103: =_xlfn.XLOOKUP(C103,kamus!$B$2:$B$87,kamus!$D$2:$D$87,"dihapus",0,1) -> Gamping 1 | C103: balecatur | D103: =_xlfn.XLOOKUP(C103,kamus!$B$2:$B$87,kamus!$J$2:$J$87,"dihapus",0,1) -> 1 | E103: =IF(D103=0,0,IF(H103<2021,0,IF(AND(H103=2021,G103<5),0,1))) -> 0 | F103: 42401 | G103: =MONTH(F103) -> 2 | H103: =YEAR(F103) -> 2016 | I103: 1 | K103: =J103+I103 -> 1 | L103: 20645 | M103: =IF(ISBLANK(I103)=TRUE,"",I103/$L103*100000) -> 4.8437878 | N103: =IF(ISBLANK(J103)=TRUE,"",J103/$L103*100000) | O103: =IF(ISBLANK(K103)=TRUE,"",K103/$L103*100000) -> 4.8437878 | Q103: =_xlfn.XLOOKUP(C103&G103&H103,covid!$E$2:$E$2184,covid!$D$2:$D$2184,0,0,1) -> 0
A104: =_xlfn.XLOOKUP(C104,kamus!$B$2:$B$87,kamus!$A$2:$A$87,0,0,1) -> 16 | B104: =_xlfn.XLOOKUP(C104,kamus!$B$2:$B$87,kamus!$D$2:$D$87,"dihapus",0,1) -> Gamping 2 | C104: banyuraden | D104: =_xlfn.XLOOKUP(C104,kamus!$B$2:$B$87,kamus!$J$2:$J$87,"dihapus",0,1) -> 1 | E104: =IF(D104=0,0,IF(H104<2021,0,IF(AND(H104=2021,G104<5),0,1))) -> 0 | F104: 42401 | G104: =MONTH(F104) -> 2 | H104: =YEAR(F104) -> 2016 | I104: 3 | K104: =J104+I104 -> 3 | L104: 16624 | M104: =IF(ISBLANK(I104)=TRUE,"",I104/$L104*100000) -> 18.046198 | N104: =IF(ISBLANK(J104)=TRUE,"",J104/$L104*100000) | O104: =IF(ISBLANK(K104)=TRUE,"",K104/$L104*100000) -> 18.046198 | Q104: =_xlfn.XLOOKUP(C104&G104&H104,covid!$E$2:$E$2184,covid!$D$2:$D$2184,0,0,1) -> 0
A105: =_xlfn.XLOOKUP(C105,kamus!$B$2:$B$87,kamus!$A$2:$A$87,0,0,1) -> 15 | B105: =_xlfn.XLOOKUP(C105,kamus!$B$2:$B$87,kamus!$D$2:$D$87,"dihapus",0,1) -> Gamping 2 | C105: nogotirto | D105: =_xlfn.XLOOKUP(C105,kamus!$B$2:$B$87,kamus!$J$2:$J$87,"dihapus",0,1) -> 1 | E105: =IF(D105=0,0,IF(H105<2021,0,IF(AND(H105=2021,G105<5),0,1))) -> 0 | F105: 42401 | G105: =MONTH(F105) -> 2 | H105: =YEAR(F105) -> 2016 | I105: 3 | K105: =J105+I105 -> 3 | L105: 18692 | M105: =IF(ISBLANK(I105)=TRUE,"",I105/$L105*100000) -> 16.049647 | N105: =IF(ISBLANK(J105)=TRUE,"",J105/$L105*100000) | O105: =IF(ISBLANK(K105)=TRUE,"",K105/$L105*100000) -> 16.049647 | Q105: =_xlfn.XLOOKUP(C105&G105&H105,covid!$E$2:$E$2184,covid!$D$2:$D$2184,0,0,1) -> 0
A106: =_xlfn.XLOOKUP(C106,kamus!$B$2:$B$87,kamus!$A$2:$A$87,0,0,1) -> 17 | B106: =_xlfn.XLOOKUP(C106,kamus!$B$2:$B$87,kamus!$D$2:$D$87,"dihapus",0,1) -> Gamping 2 | C106: trihanggo | D106: =_xlfn.XLOOKUP(C106,kamus!$B$2:$B$87,kamus!$J$2:$J$87,"dihapus",0,1) -> 1 | E106: =IF(D106=0,0,IF(H106<2021,0,IF(AND(H106=2021,G106<5),0,1))) -> 0 | F106: 42401 | G106: =MONTH(F106) -> 2 | H106: =YEAR(F106) -> 2016 | I106: 1 | K106: =J106+I106 -> 1 | L106: 18667 | M106: =IF(ISBLANK(I106)=TRUE,"",I106/$L106*100000) -> 5.3570472 | N106: =IF(ISBLANK(J106)=TRUE,"",J106/$L106*100000) | O106: =IF(ISBLANK(K106)=TRUE,"",K106/$L106*100000) -> 5.3570472 | Q106: =_xlfn.XLOOKUP(C106&G106&H106,covid!$E$2:$E$2184,covid!$D$2:$D$2184,0,0,1) -> 0
A107: =_xlfn.XLOOKUP(C107,kamus!$B$2:$B$87,kamus!$A$2:$A$87,0,0,1) -> 20 | B107: =_xlfn.XLOOKUP(C107,kamus!$B$2:$B$87,kamus!$D$2:$D$87,"dihapus",0,1) -> Godean 1 | C107: sidoagung | D107: =_xlfn.XLOOKUP(C107,kamus!$B$2:$B$87,kamus!$J$2:$J$87,"dihapus",0,1) -> 1 | E107: =IF(D107=0,0,IF(H107<2021,0,IF(AND(H107=2021,G107<5),0,1))) -> 0 | F107: 42401 | G107: =MONTH(F107) -> 2 | H107: =YEAR(F107) -> 2016 | I107: 5 | K107: =J107+I107 -> 5 | L107: 9743 | M107: =IF(ISBLANK(I107)=TRUE,"",I107/$L107*100000) -> 51.318896 | N107: =IF(ISBLANK(J107)=TRUE,"",J107/$L107*100000) | O107: =IF(ISBLANK(K107)=TRUE,"",K107/$L107*100000) -> 51.318896 | Q107: =_xlfn.XLOOKUP(C107&G107&H107,covid!$E$2:$E$2184,covid!$D$2:$D$2184,0,0,1) -> 0
A108: =_xlfn.XLOOKUP(C108,kamus!$B$2:$B$87,kamus!$A$2:$A$87,0,0,1) -> 21 | B108: =_xlfn.XLOOKUP(C108,kamus!$B$2:$B$87,kamus!$D$2:$D$87,"dihapus",0,1) -> Godean 1 | C108: sidoluhur | D108: =_xlfn.XLOOKUP(C108,kamus!$B$2:$B$87,kamus!$J$2:$J$87,"dihapus",0,1) -> 1 | E108: =IF(D108=0,0,IF(H108<2021,0,IF(AND(H108=2021,G108<5),0,1))) -> 0 | F108: 42401 | G108: =MONTH(F108) -> 2 | H108: =YEAR(F108) -> 2016 | I108: 7 | K108: =J108+I108 -> 7 | L108: 10269 | M108: =IF(ISBLANK(I108)=TRUE,"",I108/$L108*100000) -> 68.166326 | N108: =IF(ISBLANK(J108)=TRUE,"",J108/$L108*100000) | O108: =IF(ISBLANK(K108)=TRUE,"",K108/$L108*100000) -> 68.166326 | Q108: =_xlfn.XLOOKUP(C108&G108&H108,covid!$E$2:$E$2184,covid!$D$2:$D$2184,0,0,1) -> 0
A109: =_xlfn.XLOOKUP(C109,kamus!$B$2:$B$87,kamus!$A$2:$A$87,0,0,1) -> 19 | B109: =_xlfn.XLOOKUP(C109,kamus!$B$2:$B$87,kamus!$D$2:$D$87,"dihapus",0,1) -> Godean 1 | C109: sidomoyo | D109: =_xlfn.XLOOKUP(C109,kamus!$B$2:$B$87,kamus!$J$2:$J$87,"dihapus",0,1) -> 1 | E109: =IF(D109=0,0,IF(H109<2021,0,IF(AND(H109=2021,G109<5),0,1))) -> 0 | F109: 42401 | G109: =MONTH(F109) -> 2 | H109: =YEAR(F109) -> 2016 | I109: 2 | K109: =J109+I109 -> 2 | L109: 9159 | M109: =IF(ISBLANK(I109)=TRUE,"",I109/$L109*100000) -> 21.836445 | N109: =IF(ISBLANK(J109)=TRUE,"",J109/$L109*100000) | O109: =IF(ISBLANK(K109)=TRUE,"",K109/$L109*100000) -> 21.836445 | Q109: =_xlfn.XLOOKUP(C109&G109&H109,covid!$E$2:$E$2184,covid!$D$2:$D$2184,0,0,1) -> 0
A110: =_xlfn.XLOOKUP(C110,kamus!$B$2:$B$87,kamus!$A$2:$A$87,0,0,1) -> 18 | B110: =_xlfn.XLOOKUP(C110,kamus!$B$2:$B$87,kamus!$D$2:$D$87,"dihapus",0,1) -> Godean 1 | C110: sidomulyo | D110: =_xlfn.XLOOKUP(C110,kamus!$B$2:$B$87,kamus!$J$2:$J$87,"dihapus",0,1) -> 0 | E110: =IF(D110=0,0,IF(H110<2021,0,IF(AND(H110=2021,G110<5),0,1))) -> 0 | F110: 42401 | G110: =MONTH(F110) -> 2 | H110: =YEAR(F110) -> 2016 | I110: 0 | K110: =J110+I110 -> 0 | L110: 6607 | M110: =IF(ISBLANK(I110)=TRUE,"",I110/$L110*100000) -> 0 | N110: =IF(ISBLANK(J110)=TRUE,"",J110/$L110*100000) | O110: =IF(ISBLANK(K110)=TRUE,"",K110/$L110*100000) -> 0 | Q110: =_xlfn.XLOOKUP(C110&G110&H110,covid!$E$2:$E$2184,covid!$D$2:$D$2184,0,0,1) -> 0
A111: =_xlfn.XLOOKUP(C111,kamus!$B$2:$B$87,kamus!$A$2:$A$87,0,0,1) -> 23 | B111: =_xlfn.XLOOKUP(C111,kamus!$B$2:$B$87,kamus!$D$2:$D$87,"dihapus",0,1) -> Godean 2 | C111: sidoarum | D111: =_xlfn.XLOOKUP(C111,kamus!$B$2:$B$87,kamus!$J$2:$J$87,"dihapus",0,1) -> 1 | E111: =IF(D111=0,0,IF(H111<2021,0,IF(AND(H111=2021,G111<5),0,1))) -> 0 | F111: 42401 | G111: =MONTH(F111) -> 2 | H111: =YEAR(F111) -> 2016 | I111: 0 | K111: =J111+I111 -> 0 | L111: 17439 | M111: =IF(ISBLANK(I111)=TRUE,"",I111/$L111*100000) -> 0 | N111: =IF(ISBLANK(J111)=TRUE,"",J111/$L111*100000) | O111: =IF(ISBLANK(K111)=TRUE,"",K111/$L111*100000) -> 0 | Q111: =_xlfn.XLOOKUP(C111&G111&H111,covid!$E$2:$E$2184,covid!$D$2:$D$2184,0,0,1) -> 0
A112: =_xlfn.XLOOKUP(C112,kamus!$B$2:$B$87,kamus!$A$2:$A$87,0,0,1) -> 22 | B112: =_xlfn.XLOOKUP(C112,kamus!$B$2:$B$87,kamus!$D$2:$D$87,"dihapus",0,1) -> Godean 2 | C112: sidokarto | D112: =_xlfn.XLOOKUP(C112,kamus!$B$2:$B$87,kamus!$J$2:$J$87,"dihapus",0,1) -> 1 | E112: =IF(D112=0,0,IF(H112<2021,0,IF(AND(H112=2021,G112<5),0,1))) -> 0 | F112: 42401 | G112: =MONTH(F112) -> 2 | H112: =YEAR(F112) -> 2016 | I112: 0 | K112: =J112+I112 -> 0 | L112: 12380 | M112: =IF(ISBLANK(I112)=TRUE,"",I112/$L112*100000) -> 0 | N112: =IF(ISBLANK(J112)=TRUE,"",J112/$L112*100000) | O112: =IF(ISBLANK(K112)=TRUE,"",K112/$L112*100000) -> 0 | Q112: =_xlfn.XLOOKUP(C112&G112&H112,covid!$E$2:$E$2184,covid!$D$2:$D$2184,0,0,1) -> 0
A113: =_xlfn.XLOOKUP(C113,kamus!$B$2:$B$87,kamus!$A$2:$A$87,0,0,1) -> 24 | B113: =_xlfn.XLOOKUP(C113,kamus!$B$2:$B$87,kamus!$D$2:$D$87,"dihapus",0,1) -> Godean 2 | C113: sidorejo | D113: =_xlfn.XLOOKUP(C113,kamus!$B$2:$B$87,kamus!$J$2:$J$87,"dihapus",0,1) -> 0 | E113: =IF(D113=0,0,IF(H113<2021,0,IF(AND(H113=2021,G113<5),0,1))) -> 0 | F113: 42401 | G113: =MONTH(F113) -> 2 | H113: =YEAR(F113) -> 2016 | I113: 0 | K113: =J113+I113 -> 0 | L113: 7087 | M113: =IF(ISBLANK(I113)=TRUE,"",I113/$L113*100000) -> 0 | N113: =IF(ISBLANK(J113)=TRUE,"",J113/$L113*100000) | O113: =IF(ISBLANK(K113)=TRUE,"",K113/$L113*100000) -> 0 | Q113: =_xlfn.XLOOKUP(C113&G113&H113,covid!$E$2:$E$2184,covid!$D$2:$D$2184,0,0,1) -> 0
...

Sheet kab
A1: bulan | B1: kasus | C1: tahun | D1: data | F1: Fogging | G1: 2019 | H1: 2020 | I1: 2021 | J1: 2022 | K1: 2023 | L1: 2024 | M1: 2025
A2: 1 | B2: 105 | C2: 2019 | D2: DBD | F2: Jan | G2: 25 | H2: 28 | I2: 19 | J2: 21 | K2: 8
A3: 2 | B3: 104 | C3: 2019 | D3: DBD | F3: Feb | G3: 45 | H3: 27 | I3: 9 | J3: 3 | K3: 1
A4: 3 | B4: 93 | C4: 2019 | D4: DBD | F4: Mart | G4: 30 | H4: 37 | I4: 11 | J4: 6 | K4: 1
A5: 4 | B5: 93 | C5: 2019 | D5: DBD | F5: Apr | G5: 42 | H5: 45 | I5: 12 | J5: 5 | K5: 1
A6: 5 | B6: 114 | C6: 2019 | D6: DBD | F6: Mei | G6: 34 | H6: 54 | I6: 11 | J6: 4 | K6: 0
A7: 6 | B7: 64 | C7: 2019 | D7: DBD | F7: Juni | G7: 19 | H7: 54 | I7: 7 | J7: 5 | K7: 0
A8: 7 | B8: 40 | C8: 2019 | D8: DBD | F8: Juli | G8: 11 | H8: 24 | I8: 11 | J8: 5 | K8: 0
A9: 8 | B9: 19 | C9: 2019 | D9: DBD | F9: Agt | G9: 4 | H9: 4 | I9: 5 | J9: 3 | K9: 0
A10: 9 | B10: 21 | C10: 2019 | D10: DBD | F10: Sept | G10: 9 | H10: 12 | I10: 7 | J10: 4 | K10: 0
A11: 10 | B11: 23 | C11: 2019 | D11: DBD | F11: Okt | G11: 2 | H11: 8 | I11: 4 | J11: 6 | K11: 1
A12: 11 | B12: 16 | C12: 2019 | D12: DBD | F12: Nop | G12: 8 | H12: 24 | I12: 5 | J12: 4 | K12: 0
A13: 12 | B13: 18 | C13: 2019 | D13: DBD | F13: Des | G13: 13 | H13: 13 | I13: 12 | J13: 2 | K13: 0
A14: 1 | B14: 93 | C14: 2020 | D14: DBD | F14: total | G14: =SUM(G2:G13) -> 242 | H14: =SUM(H2:H13) -> 330 | I14: =SUM(I2:I13) -> 113 | J14: 65 | K14: 12
A15: 2 | B15: 102 | C15: 2020 | D15: DBD
A16: 3 | B16: 124 | C16: 2020 | D16: DBD
A17: 4 | B17: 111 | C17: 2020 | D17: DBD
A18: 5 | B18: 129 | C18: 2020 | D18: DBD
A19: 6 | B19: 81 | C19: 2020 | D19: DBD
A20: 7 | B20: 48 | C20: 2020 | D20: DBD
A21: 8 | B21: 20 | C21: 2020 | D21: DBD
A22: 9 | B22: 38 | C22: 2020 | D22: DBD
A23: 10 | B23: 16 | C23: 2020 | D23: DBD
A24: 11 | B24: 25 | C24: 2020 | D24: DBD
A25: 12 | B25: 20 | C25: 2020 | D25: DBD
A26: 1 | B26: 28 | C26: 2021 | D26: DBD
... A169: 12 | B169: 81 | C169: 2025 | D169: DD

Sheet ABJ
A1: puskesmas | B1: bulan | C1: tahun | D1: ABJ | E1: tahun bulan
A2: Berbah | B2: 1 | C2: 2022 | D2: 95.257903 | E2: =DATE(C2,B2,1) -> 44562 | H2: kurang
A3: Cangkringan | B3: 1 | C3: 2022 | D3: 90 | E3: =DATE(C3,B3,1) -> 44562 | H3: 2025 bulan desember
A4: Depok I | B4: 1 | C4: 2022 | D4: 87.980173 | E4: =DATE(C4,B4,1) -> 44562 | H4: 2021
A5: Depok II | B5: 1 | C5: 2022 | D5: 85.291214 | E5: =DATE(C5,B5,1) -> 44562 | H5: 2020
A6: Depok III | B6: 1 | C6: 2022 | D6: 73.992674 | E6: =DATE(C6,B6,1) -> 44562 | H6: 2019
A7: Gamping I | B7: 1 | C7: 2022 | D7: 95.330897 | E7: =DATE(C7,B7,1) -> 44562
A8: Gamping II | B8: 1 | C8: 2022 | D8: 90.0369 | E8: =DATE(C8,B8,1) -> 44562
A9: Godean I | B9: 1 | C9: 2022 | D9: 90.39039 | E9: =DATE(C9,B9,1) -> 44562
A10: Godean II | B10: 1 | C10: 2022 | D10: 100 | E10: =DATE(C10,B10,1) -> 44562
A11: Kalasan | B11: 1 | C11: 2022 | D11: 93.387224 | E11: =DATE(C11,B11,1) -> 44562
A12: Minggir | B12: 1 | C12: 2022 | D12: 85.912698 | E12: =DATE(C12,B12,1) -> 44562
A13: Mlati I | B13: 1 | C13: 2022 | D13: 91.538462 | E13: =DATE(C13,B13,1) -> 44562
A14: Mlati II | B14: 1 | C14: 2022 | D14: 80 | E14: =DATE(C14,B14,1) -> 44562
A15: Moyudan | B15: 1 | C15: 2022 | D15: 84.690554 | E15: =DATE(C15,B15,1) -> 44562
A16: Ngaglik I | B16: 1 | C16: 2022 | D16: 90.10989 | E16: =DATE(C16,B16,1) -> 44562
A17: Ngaglik II | B17: 1 | C17: 2022 | D17: 93.571429 | E17: =DATE(C17,B17,1) -> 44562
A18: Ngemplak I | B18: 1 | C18: 2022 | E18: =DATE(C18,B18,1) -> 44562
A19: Ngemplak II | B19: 1 | C19: 2022 | D19: 98.814815 | E19: =DATE(C19,B19,1) -> 44562
A20: Pakem | B20: 1 | C20: 2022 | D20: 93.362832 | E20: =DATE(C20,B20,1) -> 44562
A21: Prambanan | B21: 1 | C21: 2022 | D21: 94.029851 | E21: =DATE(C21,B21,1) -> 44562
A22: Seyegan | B22: 1 | C22: 2022 | D22: 91.539246 | E22: =DATE(C22,B22,1) -> 44562
A23: Sleman | B23: 1 | C23: 2022 | D23: 89.207547 | E23: =DATE(C23,B23,1) -> 44562
A24: Tempel I | B24: 1 | C24: 2022 | D24: 100 | E24: =DATE(C24,B24,1) -> 44562
A25: Tempel II | B25: 1 | C25: 2022 | E25: =DATE(C25,B25,1) -> 44562
A26: Turi | B26: 1 | C26: 2022 | D26: 95.2 | E26: =DATE(C26,B26,1) -> 44562
A27: Berbah | B27: 2 | C27: 2022 | D27: 95.057034 | E27: =DATE(C27,B27,1) -> 44593
A28: Cangkringan | B28: 2 | C28: 2022 | D28: 95 | E28: =DATE(C28,B28,1) -> 44593
A29: Depok I | B29: 2 | C29: 2022 | D29: 89.833641 | E29: =DATE(C29,B29,1) -> 44593
A30: Depok II | B30: 2 | C30: 2022 | D30: 87.332215 | E30: =DATE(C30,B30,1) -> 44593
A31: Depok III | B31: 2 | C31: 2022 | D31: 95.897436 | E31: =DATE(C31,B31,1) -> 44593
A32: Gamping I | B32: 2 | C32: 2022 | D32: 96.052061 | E32: =DATE(C32,B32,1) -> 44593
A33: Gamping II | B33: 2 | C33: 2022 | D33: 100 | E33: =DATE(C33,B33,1) -> 44593
A34: Godean I | B34: 2 | C34: 2022 | D34: 92.492492 | E34: =DATE(C34,B34,1) -> 44593
A35: Godean II | B35: 2 | C35: 2022 | D35: 57.777778 | E35: =DATE(C35,B35,1) -> 44593
A36: Kalasan | B36: 2 | C36: 2022 | D36: 96.157685 | E36: =DATE(C36,B36,1) -> 44593
A37: Minggir | B37: 2 | C37: 2022 | D37: 93.658537 | E37: =DATE(C37,B37,1) -> 44593
... A42: Ngaglik II | B42: 2 | C42: 2022 | D42: 96.666667 | E42: =DATE(C42,B42,1) -> 44593
A43: Ngemplak I | B43: 2 | C43: 2022 | E43: =DATE(C43,B43,1) -> 44593
A44: Ngemplak II | B44: 2 | C44: 2022 | D44: 96.666667 | E44: =DATE(C44,B44,1) -> 44593
...

Sheet covid
A1: desa fix | B1: Years (Tanggal Lapor) | C1: Months (Tanggal Lapor) | D1: Sum of Count of Nama | E1: kode
A2: ambarketawang | B2: 2020 | C2: 5 | D2: 1 | E2: =A2&C2&B2 -> ambarketawang52020
A3: ambarketawang | B3: 2020 | C3: 7 | D3: 2 | E3: =A3&C3&B3 -> ambarketawang72020
A4: ambarketawang | B4: 2020 | C4: 10 | D4: 1 | E4: =A4&C4&B4 -> ambarketawang102020
A5: ambarketawang | B5: 2020 | C5: 11 | D5: 4 | E5: =A5&C5&B5 -> ambarketawang112020
A6: ambarketawang | B6: 2020 | C6: 12 | D6: 42 | E6: =A6&C6&B6 -> ambarketawang122020
A7: ambarketawang | B7: 2021 | C7: 1 | D7: 43 | E7: =A7&C7&B7 -> ambarketawang12021
A8: ambarketawang | B8: 2021 | C8: 2 | D8: 25 | E8: =A8&C8&B8 -> ambarketawang22021
A9: ambarketawang | B9: 2021 | C9: 3 | D9: 21 | E9: =A9&C9&B9 -> ambarketawang32021
A10: ambarketawang | B10: 2021 | C10: 4 | D10: 50 | E10: =A10&C10&B10 -> ambarketawang42021
A11: ambarketawang | B11: 2021 | C11: 5 | D11: 15 | E11: =A11&C11&B11 -> ambarketawang52021
A12: ambarketawang | B12: 2021 | C12: 6 | D12: 92 | E12: =A12&C12&B12 -> ambarketawang62021
A13: ambarketawang | B13: 2021 | C13: 7 | D13: 161 | E13: =A13&C13&B13 -> ambarketawang72021
... A2184: wukirsari | B2184: 2024 | C2184: 12 | D2184: 1 | E2184: =A2184&C2184&B2184 -> wukirsari122024
